[2024-04-12T00:17:49.725+0000] {local_task_job_runner.py:120} INFO - ::group::Pre task execution logs
[2024-04-12T00:17:49.757+0000] {taskinstance.py:2073} INFO - Dependencies all met for dep_context=non-requeueable deps ti=<TaskInstance: tutorial_dag.transformar_dados_em_dataframe scheduled__2024-04-11T22:30:00+00:00 [queued]>
[2024-04-12T00:17:49.765+0000] {taskinstance.py:2073} INFO - Dependencies all met for dep_context=requeueable deps ti=<TaskInstance: tutorial_dag.transformar_dados_em_dataframe scheduled__2024-04-11T22:30:00+00:00 [queued]>
[2024-04-12T00:17:49.766+0000] {taskinstance.py:2303} INFO - Starting attempt 2 of 2
[2024-04-12T00:17:50.334+0000] {taskinstance.py:2327} INFO - Executing <Task(PythonOperator): transformar_dados_em_dataframe> on 2024-04-11 22:30:00+00:00
[2024-04-12T00:17:50.350+0000] {standard_task_runner.py:90} INFO - Running: ['***', 'tasks', 'run', 'tutorial_dag', 'transformar_dados_em_dataframe', 'scheduled__2024-04-11T22:30:00+00:00', '--job-id', '9', '--raw', '--subdir', 'DAGS_FOLDER/tutorial_dag.py', '--cfg-path', '/tmp/tmp9z6pyfzv']
[2024-04-12T00:17:50.353+0000] {logging_mixin.py:188} WARNING - /home/***/.local/lib/python3.12/site-packages/***/task/task_runner/standard_task_runner.py:61 DeprecationWarning: This process (pid=801) is multi-threaded, use of fork() may lead to deadlocks in the child.
[2024-04-12T00:17:50.354+0000] {standard_task_runner.py:91} INFO - Job 9: Subtask transformar_dados_em_dataframe
[2024-04-12T00:17:50.354+0000] {standard_task_runner.py:63} INFO - Started process 803 to run task
[2024-04-12T00:17:50.433+0000] {task_command.py:426} INFO - Running <TaskInstance: tutorial_dag.transformar_dados_em_dataframe scheduled__2024-04-11T22:30:00+00:00 [running]> on host ae99acc4965a
[2024-04-12T00:17:50.540+0000] {taskinstance.py:2644} INFO - Exporting env vars: AIRFLOW_CTX_DAG_OWNER='***' AIRFLOW_CTX_DAG_ID='tutorial_dag' AIRFLOW_CTX_TASK_ID='transformar_dados_em_dataframe' AIRFLOW_CTX_EXECUTION_DATE='2024-04-11T22:30:00+00:00' AIRFLOW_CTX_TRY_NUMBER='2' AIRFLOW_CTX_DAG_RUN_ID='scheduled__2024-04-11T22:30:00+00:00'
[2024-04-12T00:17:50.542+0000] {taskinstance.py:430} INFO - ::endgroup::
[2024-04-12T00:17:50.559+0000] {taskinstance.py:441} INFO - ::group::Post task execution logs
[2024-04-12T00:17:50.559+0000] {taskinstance.py:2890} ERROR - Task failed with exception
Traceback (most recent call last):
  File "/home/airflow/.local/lib/python3.12/site-packages/airflow/models/taskinstance.py", line 465, in _execute_task
    result = _execute_callable(context=context, **execute_callable_kwargs)
             ^^^^^^^^^^^^^^^^^^^^^^^^^^^^^^^^^^^^^^^^^^^^^^^^^^^^^^^^^^^^^
  File "/home/airflow/.local/lib/python3.12/site-packages/airflow/models/taskinstance.py", line 432, in _execute_callable
    return execute_callable(context=context, **execute_callable_kwargs)
           ^^^^^^^^^^^^^^^^^^^^^^^^^^^^^^^^^^^^^^^^^^^^^^^^^^^^^^^^^^^^
  File "/home/airflow/.local/lib/python3.12/site-packages/airflow/models/baseoperator.py", line 400, in wrapper
    return func(self, *args, **kwargs)
           ^^^^^^^^^^^^^^^^^^^^^^^^^^^
  File "/home/airflow/.local/lib/python3.12/site-packages/airflow/operators/python.py", line 235, in execute
    return_value = self.execute_callable()
                   ^^^^^^^^^^^^^^^^^^^^^^^
  File "/home/airflow/.local/lib/python3.12/site-packages/airflow/operators/python.py", line 252, in execute_callable
    return self.python_callable(*self.op_args, **self.op_kwargs)
           ^^^^^^^^^^^^^^^^^^^^^^^^^^^^^^^^^^^^^^^^^^^^^^^^^^^^^
  File "/opt/airflow/dags/tutorial_dag.py", line 22, in transformar_dados_em_dataframe
    data = ti.xcom_pull(task_id = 'consumir_api_pokemons')
           ^^^^^^^^^^^^^^^^^^^^^^^^^^^^^^^^^^^^^^^^^^^^^^^
  File "/home/airflow/.local/lib/python3.12/site-packages/airflow/utils/session.py", line 79, in wrapper
    return func(*args, session=session, **kwargs)
           ^^^^^^^^^^^^^^^^^^^^^^^^^^^^^^^^^^^^^^
TypeError: TaskInstance.xcom_pull() got an unexpected keyword argument 'task_id'
[2024-04-12T00:17:50.570+0000] {taskinstance.py:1205} INFO - Marking task as FAILED. dag_id=tutorial_dag, task_id=transformar_dados_em_dataframe, execution_date=20240411T223000, start_date=20240412T001749, end_date=20240412T001750
[2024-04-12T00:17:50.581+0000] {standard_task_runner.py:110} ERROR - Failed to execute job 9 for task transformar_dados_em_dataframe (TaskInstance.xcom_pull() got an unexpected keyword argument 'task_id'; 803)
[2024-04-12T00:17:50.618+0000] {local_task_job_runner.py:240} INFO - Task exited with return code 1
[2024-04-12T00:17:50.639+0000] {taskinstance.py:3482} INFO - 0 downstream tasks scheduled from follow-on schedule check
[2024-04-12T00:17:50.641+0000] {local_task_job_runner.py:222} INFO - ::endgroup::
